Workbook

Sheet MLE Model
A1: CustomerID | B1: Age | C1: AnnualIncome | D1: TotalPurchasesLastYear | E1: AvgOrderValue | F1: WebsiteVisitsLastMonth | G1: EmailOpenRate | H1: DaysSinceLastPurchase | I1: LoyaltyMember | J1: DiscountUsedBefore | K1: SocialMediaEngagement | L1: RespondedToCampaign | M1: Baseline Score (Logit, z) | N1: Baseline Probability (p) | O1: Likelihood | P1: Log-Likelihood | R1: Intercept | S1: b_Age | T1: b_Income | U1: b_TotPurch | V1: b_AOV | W1: b_WebVisits | X1: b_EmailOpen | Y1: b_DaysSince | Z1: b_Loyalty | AA1: b_Discount | AB1: b_SocialMedia | AD1: Age (unch.) | AE1: Income (unch.) | AF1: TotPurch (unch.) | AG1: AvgOrderValue x0.85 | AH1: WebVisits x0.90 | AI1: EmailOpen (unch.) | AJ1: DaysSince x1.20 | AK1: Loyalty (unch.) | AL1: Discount (unch.) | AM1: SocialMedia (unch.) | AN1: Intervention Score (Logit) | AO1: Intervention Probability
A2: CUST1000 | B2: 56 | C2: 93200 | D2: 8 | E2: 39.74 | F2: 4 | G2: 0.58 | H2: 228 | I2: 1 | J2: 0 | K2: 0.04 | L2: 1 | M2: =$R$2 + SUMPRODUCT(B2:K2,$S$2:$AB$2) -> 0.28698892 | N2: =1/(1+EXP(-M2)) -> 0.57125881 | O2: =IF(L2=1,N2,1-N2) -> 0.57125881 | P2: =LN(O2) -> -0.55991291 | R2: -4.136772 | S2: -0.011531 | T2: 2.3e-05 | U2: 0.189009 | V2: 0.013433 | W2: 0.116063 | X2: 1.651471 | Y2: -0.005758 | Z2: 0.725131 | AA2: 0.629504 | AB2: 1.139633 | AD2: =B2 -> 56 | AE2: =C2 -> 93200 | AF2: =D2 -> 8 | AG2: =E2*0.85 -> 33.779 | AH2: =F2*0.9 -> 3.6 | AI2: =G2 -> 0.58 | AJ2: =H2*1.2 -> 273.6 | AK2: =I2 -> 1 | AL2: =J2 -> 0 | AM2: =K2 -> 0.04 | AN2: =$R$2 + SUMPRODUCT(AD2:AM2,$S$2:$AB$2) -> -0.10207519 | AO2: =1/(1+EXP(-AN2)) -> 0.47450334
A3: CUST1001 | B3: 69 | C3: 73600 | D3: 4 | E3: 52.12 | F3: 3 | G3: 0.62 | H3: 79 | I3: 0 | J3: 1 | K3: 0.34 | L3: 1 | M3: =$R$2 + SUMPRODUCT(B3:K3,$S$2:$AB$2) -> 0.1507512 | N3: =1/(1+EXP(-M3)) -> 0.53761659 | O3: =IF(L3=1,N3,1-N3) -> 0.53761659 | P3: =LN(O3) -> -0.62060964 | AD3: =B3 -> 69 | AE3: =C3 -> 73600 | AF3: =D3 -> 4 | AG3: =E3*0.85 -> 44.302 | AH3: =F3*0.9 -> 2.7 | AI3: =G3 -> 0.62 | AJ3: =H3*1.2 -> 94.8 | AK3: =I3 -> 0 | AL3: =J3 -> 1 | AM3: =K3 -> 0.34 | AN3: =$R$2 + SUMPRODUCT(AD3:AM3,$S$2:$AB$2) -> -0.080063294 | AO3: =1/(1+EXP(-AN3)) -> 0.47999486
A4: CUST1002 | B4: 46 | C4: 27700 | D4: 3 | E4: 103.25 | F4: 6 | G4: 0.74 | H4: 96 | I4: 1 | J4: 0 | K4: 0.03 | L4: 1 | M4: =$R$2 + SUMPRODUCT(B4:K4,$S$2:$AB$2) -> 0.04890478 | N4: =1/(1+EXP(-M4)) -> 0.51222376 | O4: =IF(L4=1,N4,1-N4) -> 0.51222376 | P4: =LN(O4) -> -0.66899372 | Q4: Total Log-Likelihood (Solver Objective, Max): | R4: =SUM(P2:P501) -> -287.60498 | AD4: =B4 -> 46 | AE4: =C4 -> 27700 | AF4: =D4 -> 3 | AG4: =E4*0.85 -> 87.7625 | AH4: =F4*0.9 -> 5.4 | AI4: =G4 -> 0.74 | AJ4: =H4*1.2 -> 115.2 | AK4: =I4 -> 1 | AL4: =J4 -> 0 | AM4: =K4 -> 0.03 | AN4: =$R$2 + SUMPRODUCT(AD4:AM4,$S$2:$AB$2) -> -0.33933021 | AO4: =1/(1+EXP(-AN4)) -> 0.41597219
A5: CUST1003 | B5: 32 | C5: 46300 | D5: 9 | E5: 81.62 | F5: 2 | G5: 0.38 | H5: 349 | I5: 0 | J5: 0 | K5: 0.44 | L5: 0 | M5: =$R$2 + SUMPRODUCT(B5:K5,$S$2:$AB$2) -> -1.2918 | N5: =1/(1+EXP(-M5)) -> 0.21554829 | O5: =IF(L5=1,N5,1-N5) -> 0.78445171 | P5: =LN(O5) -> -0.24277027 | AD5: =B5 -> 32 | AE5: =C5 -> 46300 | AF5: =D5 -> 9 | AG5: =E5*0.85 -> 69.377 | AH5: =F5*0.9 -> 1.8 | AI5: =G5 -> 0.38 | AJ5: =H5*1.2 -> 418.8 | AK5: =I5 -> 0 | AL5: =J5 -> 0 | AM5: =K5 -> 0.44 | AN5: =$R$2 + SUMPRODUCT(AD5:AM5,$S$2:$AB$2) -> -1.8813813 | AO5: =1/(1+EXP(-AN5)) -> 0.1322303
A6: CUST1004 | B6: 60 | C6: 77800 | D6: 5 | E6: 41.89 | F6: 2 | G6: 0.35 | H6: 330 | I6: 0 | J6: 0 | K6: 0.16 | L6: 0 | M6: =$R$2 + SUMPRODUCT(B6:K6,$S$2:$AB$2) -> -2.4391365 | N6: =1/(1+EXP(-M6)) -> 0.080236614 | O6: =IF(L6=1,N6,1-N6) -> 0.91976339 | P6: =LN(O6) -> -0.083638831 | Q6: Baseline Avg Probability of Response: | R6: =AVERAGE(N2:N501) -> 0.44669992 | AD6: =B6 -> 60 | AE6: =C6 -> 77800 | AF6: =D6 -> 5 | AG6: =E6*0.85 -> 35.6065 | AH6: =F6*0.9 -> 1.8 | AI6: =G6 -> 0.35 | AJ6: =H6*1.2 -> 396 | AK6: =I6 -> 0 | AL6: =J6 -> 0 | AM6: =K6 -> 0.16 | AN6: =$R$2 + SUMPRODUCT(AD6:AM6,$S$2:$AB$2) -> -2.9267834 | AO6: =1/(1+EXP(-AN6)) -> 0.050845336
A7: CUST1005 | B7: 25 | C7: 42300 | D7: 9 | E7: 25.06 | F7: 3 | G7: 0.59 | H7: 246 | I7: 0 | J7: 0 | K7: 0.55 | L7: 0 | M7: =$R$2 + SUMPRODUCT(B7:K7,$S$2:$AB$2) -> -0.88154798 | N7: =1/(1+EXP(-M7)) -> 0.2928571 | O7: =IF(L7=1,N7,1-N7) -> 0.7071429 | P7: =LN(O7) -> -0.34652251 | Q7: Baseline Total Expected Revenue ($): | R7: =SUMPRODUCT(E2:E501,N2:N501) -> 15193.308 | AD7: =B7 -> 25 | AE7: =C7 -> 42300 | AF7: =D7 -> 9 | AG7: =E7*0.85 -> 21.301 | AH7: =F7*0.9 -> 2.7 | AI7: =G7 -> 0.59 | AJ7: =H7*1.2 -> 295.2 | AK7: =I7 -> 0 | AL7: =J7 -> 0 | AM7: =K7 -> 0.55 | AN7: =$R$2 + SUMPRODUCT(AD7:AM7,$S$2:$AB$2) -> -1.2501551 | AO7: =1/(1+EXP(-AN7)) -> 0.22267329
A8: CUST1006 | B8: 38 | C8: 63000 | D8: 6 | E8: 56.82 | F8: 5 | G8: 0.46 | H8: 272 | I8: 0 | J8: 1 | K8: 0.63 | L8: 0 | M8: =$R$2 + SUMPRODUCT(B8:K8,$S$2:$AB$2) -> -0.10734449 | N8: =1/(1+EXP(-M8)) -> 0.47318962 | O8: =IF(L8=1,N8,1-N8) -> 0.52681038 | P8: =LN(O8) -> -0.6409146 | Q8: # Customers Targeted (p > 0.5): | R8: =COUNTIF(N2:N501,">0.5") -> 212 | AD8: =B8 -> 38 | AE8: =C8 -> 63000 | AF8: =D8 -> 6 | AG8: =E8*0.85 -> 48.297 | AH8: =F8*0.9 -> 4.5 | AI8: =G8 -> 0.46 | AJ8: =H8*1.2 -> 326.4 | AK8: =I8 -> 0 | AL8: =J8 -> 1 | AM8: =K8 -> 0.63 | AN8: =$R$2 + SUMPRODUCT(AD8:AM8,$S$2:$AB$2) -> -0.59310065 | AO8: =1/(1+EXP(-AN8)) -> 0.35592374
A9: CUST1007 | B9: 56 | C9: 68900 | D9: 8 | E9: 59.66 | F9: 1 | G9: 0.51 | H9: 157 | I9: 0 | J9: 1 | K9: 0.33 | L9: 1 | M9: =$R$2 + SUMPRODUCT(B9:K9,$S$2:$AB$2) -> 0.17556688 | N9: =1/(1+EXP(-M9)) -> 0.54377932 | O9: =IF(L9=1,N9,1-N9) -> 0.54377932 | P9: =LN(O9) -> -0.60921177 | Q9: Total Marketing Cost ($5/customer): | R9: =R8*5 -> 1060 | AD9: =B9 -> 56 | AE9: =C9 -> 68900 | AF9: =D9 -> 8 | AG9: =E9*0.85 -> 50.711 | AH9: =F9*0.9 -> 0.9 | AI9: =G9 -> 0.51 | AJ9: =H9*1.2 -> 188.4 | AK9: =I9 -> 0 | AL9: =J9 -> 1 | AM9: =K9 -> 0.33 | AN9: =$R$2 + SUMPRODUCT(AD9:AM9,$S$2:$AB$2) -> -0.13705254 | AO9: =1/(1+EXP(-AN9)) -> 0.4657904
A10: CUST1008 | B10: 36 | C10: 38300 | D10: 6 | E10: 77.4 | F10: 4 | G10: 0.59 | H10: 116 | I10: 0 | J10: 1 | K10: 0.51 | L10: 1 | M10: =$R$2 + SUMPRODUCT(B10:K10,$S$2:$AB$2) -> 0.48418892 | N10: =1/(1+EXP(-M10)) -> 0.61873654 | O10: =IF(L10=1,N10,1-N10) -> 0.61873654 | P10: =LN(O10) -> -0.48007572 | Q10: Expected Acquisitions (Σ p among targeted): | R10: =SUMPRODUCT((N2:N501>0.5)*N2:N501) -> 140.9995 | AD10: =B10 -> 36 | AE10: =C10 -> 38300 | AF10: =D10 -> 6 | AG10: =E10*0.85 -> 65.79 | AH10: =F10*0.9 -> 3.6 | AI10: =G10 -> 0.59 | AJ10: =H10*1.2 -> 139.2 | AK10: =I10 -> 0 | AL10: =J10 -> 1 | AM10: =K10 -> 0.51 | AN10: =$R$2 + SUMPRODUCT(AD10:AM10,$S$2:$AB$2) -> 0.14822099 | AO10: =1/(1+EXP(-AN10)) -> 0.53698756
A11: CUST1009 | B11: 40 | C11: 53900 | D11: 3 | E11: 51.62 | F11: 2 | G11: 0.79 | H11: 18 | I11: 1 | J11: 0 | K11: 0.37 | L11: 1 | M11: =$R$2 + SUMPRODUCT(B11:K11,$S$2:$AB$2) -> 0.48206576 | N11: =1/(1+EXP(-M11)) -> 0.61823556 | O11: =IF(L11=1,N11,1-N11) -> 0.61823556 | P11: =LN(O11) -> -0.48088574 | Q11: Baseline Cost per Acquisition (CPA, $): | R11: =R9/R10 -> 7.517757 | AD11: =B11 -> 40 | AE11: =C11 -> 53900 | AF11: =D11 -> 3 | AG11: =E11*0.85 -> 43.877 | AH11: =F11*0.9 -> 1.8 | AI11: =G11 -> 0.79 | AJ11: =H11*1.2 -> 21.6 | AK11: =I11 -> 1 | AL11: =J11 -> 0 | AM11: =K11 -> 0.37 | AN11: =$R$2 + SUMPRODUCT(AD11:AM11,$S$2:$AB$2) -> 0.33411264 | AO11: =1/(1+EXP(-AN11)) -> 0.58275971
A12: CUST1010 | B12: 28 | C12: 15000 | D12: 5 | E12: 77.79 | F12: 1 | G12: 0.17 | H12: 172 | I12: 0 | J12: 1 | K12: 0.18 | L12: 0 | M12: =$R$2 + SUMPRODUCT(B12:K12,$S$2:$AB$2) -> -1.8835669 | N12: =1/(1+EXP(-M12)) -> 0.13197971 | O12: =IF(L12=1,N12,1-N12) -> 0.86802029 | P12: =LN(O12) -> -0.14154019 | AD12: =B12 -> 28 | AE12: =C12 -> 15000 | AF12: =D12 -> 5 | AG12: =E12*0.85 -> 66.1215 | AH12: =F12*0.9 -> 0.9 | AI12: =G12 -> 0.17 | AJ12: =H12*1.2 -> 206.4 | AK12: =I12 -> 0 | AL12: =J12 -> 1 | AM12: =K12 -> 0.18 | AN12: =$R$2 + SUMPRODUCT(AD12:AM12,$S$2:$AB$2) -> -2.2499914 | AO12: =1/(1+EXP(-AN12)) -> 0.095350208
A13: CUST1011 | B13: 28 | C13: 36600 | D13: 4 | E13: 113.38 | F13: 2 | G13: 0.38 | H13: 16 | I13: 0 | J13: 1 | K13: 0.27 | L13: 1 | M13: =$R$2 + SUMPRODUCT(B13:K13,$S$2:$AB$2) -> 0.36599143 | N13: =1/(1+EXP(-M13)) -> 0.59049001 | O13: =IF(L13=1,N13,1-N13) -> 0.59049001 | P13: =LN(O13) -> -0.52680256 | Q13: Intervention Avg Probability of Response: | R13: =AVERAGE(AO2:AO501) -> 0.37524111 | AD13: =B13 -> 28 | AE13: =C13 -> 36600 | AF13: =D13 -> 4 | AG13: =E13*0.85 -> 96.373 | AH13: =F13*0.9 -> 1.8 | AI13: =G13 -> 0.38 | AJ13: =H13*1.2 -> 19.2 | AK13: =I13 -> 0 | AL13: =J13 -> 1 | AM13: =K13 -> 0.27 | AN13: =$R$2 + SUMPRODUCT(AD13:AM13,$S$2:$AB$2) -> 0.095898199 | AO13: =1/(1+EXP(-AN13)) -> 0.52395619
A14: CUST1012 | B14: 41 | C14: 50500 | D14: 7 | E14: 85.39 | F14: 4 | G14: 0.2 | H14: 240 | I14: 0 | J14: 1 | K14: 0.06 | L14: 1 | M14: =$R$2 + SUMPRODUCT(B14:K14,$S$2:$AB$2) -> -0.86742795 | N14: =1/(1+EXP(-M14)) -> 0.29578977 | O14: =IF(L14=1,N14,1-N14) -> 0.29578977 | P14: =LN(O14) -> -1.2181063 | Q14: Intervention Total Expected Revenue ($): | R14: =SUMPRODUCT(AG2:AG501,AO2:AO501) -> 10827.1 | AD14: =B14 -> 41 | AE14: =C14 -> 50500 | AF14: =D14 -> 7 | AG14: =E14*0.85 -> 72.5815 | AH14: =F14*0.9 -> 3.6 | AI14: =G14 -> 0.2 | AJ14: =H14*1.2 -> 288 | AK14: =I14 -> 0 | AL14: =J14 -> 1 | AM14: =K14 -> 0.06 | AN14: =$R$2 + SUMPRODUCT(AD14:AM14,$S$2:$AB$2) -> -1.3622937 | AO14: =1/(1+EXP(-AN14)) -> 0.20386776
A15: CUST1013 | B15: 53 | C15: 32500 | D15: 10 | E15: 63.8 | F15: 4 | G15: 0.42 | H15: 56 | I15: 0 | J15: 0 | K15: 0.23 | L15: 0 | M15: =$R$2 + SUMPRODUCT(B15:K15,$S$2:$AB$2) -> -0.15576219 | N15: =1/(1+EXP(-M15)) -> 0.46113799 | O15: =IF(L15=1,N15,1-N15) -> 0.53886201 | P15: =LN(O15) -> -0.61829576 | Q15: # Customers Targeted, Intervention (p > 0.5): | R15: =COUNTIF(AO2:AO501,">0.5") -> 145 | AD15: =B15 -> 53 | AE15: =C15 -> 32500 | AF15: =D15 -> 10 | AG15: =E15*0.85 -> 54.23 | AH15: =F15*0.9 -> 3.6 | AI15: =G15 -> 0.42 | AJ15: =H15*1.2 -> 67.2 | AK15: =I15 -> 0 | AL15: =J15 -> 0 | AM15: =K15 -> 0.23 | AN15: =$R$2 + SUMPRODUCT(AD15:AM15,$S$2:$AB$2) -> -0.3952308 | AO15: =1/(1+EXP(-AN15)) -> 0.40245873
A16: CUST1014 | B16: 57 | C16: 84400 | D16: 4 | E16: 60.42 | F16: 2 | G16: 0.64 | H16: 79 | I16: 0 | J16: 1 | K16: 0.86 | L16: 1 | M16: =$R$2 + SUMPRODUCT(B16:K16,$S$2:$AB$2) -> 1.1585927 | N16: =1/(1+EXP(-M16)) -> 0.7610769 | O16: =IF(L16=1,N16,1-N16) -> 0.7610769 | P16: =LN(O16) -> -0.27302087 | Q16: Intervention Total Marketing Cost ($): | R16: =R15*5 -> 725 | AD16: =B16 -> 57 | AE16: =C16 -> 84400 | AF16: =D16 -> 4 | AG16: =E16*0.85 -> 51.357 | AH16: =F16*0.9 -> 1.8 | AI16: =G16 -> 0.64 | AJ16: =H16*1.2 -> 94.8 | AK16: =I16 -> 0 | AL16: =J16 -> 1 | AM16: =K16 -> 0.86 | AN16: =$R$2 + SUMPRODUCT(AD16:AM16,$S$2:$AB$2) -> 0.9226604 | AO16: =1/(1+EXP(-AN16)) -> 0.71558387
A17: CUST1015 | B17: 41 | C17: 29300 | D17: 1 | E17: 56.08 | F17: 9 | G17: 0.39 | H17: 103 | I17: 0 | J17: 0 | K17: 0.68 | L17: 0 | M17: =$R$2 + SUMPRODUCT(B17:K17,$S$2:$AB$2) -> -1.1227942 | N17: =1/(1+EXP(-M17)) -> 0.24549335 | O17: =IF(L17=1,N17,1-N17) -> 0.75450665 | P17: =LN(O17) -> -0.28169119 | Q17: Intervention Expected Acquisitions: | R17: =SUMPRODUCT((AO2:AO501>0.5)*AO2:AO501) -> 96.173751 | AD17: =B17 -> 41 | AE17: =C17 -> 29300 | AF17: =D17 -> 1 | AG17: =E17*0.85 -> 47.668 | AH17: =F17*0.9 -> 8.1 | AI17: =G17 -> 0.39 | AJ17: =H17*1.2 -> 123.6 | AK17: =I17 -> 0 | AL17: =J17 -> 0 | AM17: =K17 -> 0.68 | AN17: =$R$2 + SUMPRODUCT(AD17:AM17,$S$2:$AB$2) -> -1.4588641 | AO17: =1/(1+EXP(-AN17)) -> 0.18864112
A18: CUST1016 | B18: 20 | C18: 47100 | D18: 7 | E18: 94.52 | F18: 4 | G18: 0.58 | H18: 284 | I18: 0 | J18: 1 | K18: 0.31 | L18: 0 | M18: =$R$2 + SUMPRODUCT(B18:K18,$S$2:$AB$2) -> 0.07828157 | N18: =1/(1+EXP(-M18)) -> 0.5195604 | O18: =IF(L18=1,N18,1-N18) -> 0.4804396 | P18: =LN(O18) -> -0.73305377 | Q18: Intervention Cost per Acquisition (CPA, $): | R18: =R16/R17 -> 7.5384394 | AD18: =B18 -> 20 | AE18: =C18 -> 47100 | AF18: =D18 -> 7 | AG18: =E18*0.85 -> 80.342 | AH18: =F18*0.9 -> 3.6 | AI18: =G18 -> 0.58 | AJ18: =H18*1.2 -> 340.8 | AK18: =I18 -> 0 | AL18: =J18 -> 1 | AM18: =K18 -> 0.31 | AN18: =$R$2 + SUMPRODUCT(AD18:AM18,$S$2:$AB$2) -> -0.4856511 | AO18: =1/(1+EXP(-AN18)) -> 0.38091859
A19: CUST1017 | B19: 39 | C19: 57400 | D19: 9 | E19: 49.32 | F19: 5 | G19: 0.22 | H19: 193 | I19: 0 | J19: 1 | K19: 0.47 | L19: 1 | M19: =$R$2 + SUMPRODUCT(B19:K19,$S$2:$AB$2) -> 0.09479169 | N19: =1/(1+EXP(-M19)) -> 0.52368019 | O19: =IF(L19=1,N19,1-N19) -> 0.52368019 | P19: =LN(O19) -> -0.6468741 | AD19: =B19 -> 39 | AE19: =C19 -> 57400 | AF19: =D19 -> 9 | AG19: =E19*0.85 -> 41.922 | AH19: =F19*0.9 -> 4.5 | AI19: =G19 -> 0.22 | AJ19: =H19*1.2 -> 231.6 | AK19: =I19 -> 0 | AL19: =J19 -> 1 | AM19: =K19 -> 0.47 | AN19: =$R$2 + SUMPRODUCT(AD19:AM19,$S$2:$AB$2) -> -0.28487594 | AO19: =1/(1+EXP(-AN19)) -> 0.42925878
A20: CUST1018 | B20: 19 | C20: 80900 | D20: 5 | E20: 66.13 | F20: 4 | G20: 0.37 | H20: 5 | I20: 1 | J20: 1 | K20: 0.52 | L20: 1 | M20: =$R$2 + SUMPRODUCT(B20:K20,$S$2:$AB$2) -> 2.3319587 | N20: =1/(1+EXP(-M20)) -> 0.91148949 | O20: =IF(L20=1,N20,1-N20) -> 0.91148949 | P20: =LN(O20) -> -0.092675219 | Q20: SOLVER PARAMETERS (for live re-optimization in Excel) | AD20: =B20 -> 19 | AE20: =C20 -> 80900 | AF20: =D20 -> 5 | AG20: =E20*0.85 -> 56.2105 | AH20: =F20*0.9 -> 3.6 | AI20: =G20 -> 0.37 | AJ20: =H20*1.2 -> 6 | AK20: =I20 -> 1 | AL20: =J20 -> 1 | AM20: =K20 -> 0.52 | AN20: =$R$2 + SUMPRODUCT(AD20:AM20,$S$2:$AB$2) -> 2.1465269 | AO20: =1/(1+EXP(-AN20)) -> 0.89534378
A21: CUST1019 | B21: 41 | C21: 29200 | D21: 7 | E21: 66.28 | F21: 3 | G21: 0.74 | H21: 106 | I21: 0 | J21: 0 | K21: 0.46 | L21: 0 | M21: =$R$2 + SUMPRODUCT(B21:K21,$S$2:$AB$2) -> -0.24038004 | N21: =1/(1+EXP(-M21)) -> 0.4401927 | O21: =IF(L21=1,N21,1-N21) -> 0.5598073 | P21: =LN(O21) -> -0.58016266 | Q21: Set Objective | R21: $R$4 | AD21: =B21 -> 41 | AE21: =C21 -> 29200 | AF21: =D21 -> 7 | AG21: =E21*0.85 -> 56.338 | AH21: =F21*0.9 -> 2.7 | AI21: =G21 -> 0.74 | AJ21: =H21*1.2 -> 127.2 | AK21: =I21 -> 0 | AL21: =J21 -> 0 | AM21: =K21 -> 0.46 | AN21: =$R$2 + SUMPRODUCT(AD21:AM21,$S$2:$AB$2) -> -0.53081943 | AO21: =1/(1+EXP(-AN21)) -> 0.37032579
A22: CUST1020 | B22: 61 | C22: 75900 | D22: 6 | E22: 52.46 | F22: 6 | G22: 0.26 | H22: 278 | I22: 0 | J22: 0 | K22: 0.12 | L22: 0 | M22: =$R$2 + SUMPRODUCT(B22:K22,$S$2:$AB$2) -> -1.5939214 | N22: =1/(1+EXP(-M22)) -> 0.1688329 | O22: =IF(L22=1,N22,1-N22) -> 0.8311671 | P22: =LN(O22) -> -0.18492442 | Q22: To | R22: Max | AD22: =B22 -> 61 | AE22: =C22 -> 75900 | AF22: =D22 -> 6 | AG22: =E22*0.85 -> 44.591 | AH22: =F22*0.9 -> 5.4 | AI22: =G22 -> 0.26 | AJ22: =H22*1.2 -> 333.6 | AK22: =I22 -> 0 | AL22: =J22 -> 0 | AM22: =K22 -> 0.12 | AN22: =$R$2 + SUMPRODUCT(AD22:AM22,$S$2:$AB$2) -> -2.0894083 | AO22: =1/(1+EXP(-AN22)) -> 0.11013055
A23: CUST1021 | B23: 47 | C23: 55200 | D23: 6 | E23: 30.69 | F23: 5 | G23: 0.07 | H23: 100 | I23: 1 | J23: 1 | K23: 0.07 | L23: 0 | M23: =$R$2 + SUMPRODUCT(B23:K23,$S$2:$AB$2) -> -0.30828895 | N23: =1/(1+EXP(-M23)) -> 0.42353244 | O23: =IF(L23=1,N23,1-N23) -> 0.57646756 | P23: =LN(O23) -> -0.55083621 | Q23: By Changing Variable Cells | R23: $R$2:$AB$2 | AD23: =B23 -> 47 | AE23: =C23 -> 55200 | AF23: =D23 -> 6 | AG23: =E23*0.85 -> 26.0865 | AH23: =F23*0.9 -> 4.5 | AI23: =G23 -> 0.07 | AJ23: =H23*1.2 -> 120 | AK23: =I23 -> 1 | AL23: =J23 -> 1 | AM23: =K23 -> 0.07 | AN23: =$R$2 + SUMPRODUCT(AD23:AM23,$S$2:$AB$2) -> -0.54331927 | AO23: =1/(1+EXP(-AN23)) -> 0.36741577
A24: CUST1022 | B24: 55 | C24: 37300 | D24: 9 | E24: 73.07 | F24: 5 | G24: 0.19 | H24: 238 | I24: 1 | J24: 1 | K24: 0.46 | L24: 0 | M24: =$R$2 + SUMPRODUCT(B24:K24,$S$2:$AB$2) -> 0.17210998 | N24: =1/(1+EXP(-M24)) -> 0.5429216 | O24: =IF(L24=1,N24,1-N24) -> 0.4570784 | P24: =LN(O24) -> -0.78290034 | Q24: Constraints | R24: None | AD24: =B24 -> 55 | AE24: =C24 -> 37300 | AF24: =D24 -> 9 | AG24: =E24*0.85 -> 62.1095 | AH24: =F24*0.9 -> 4.5 | AI24: =G24 -> 0.19 | AJ24: =H24*1.2 -> 285.6 | AK24: =I24 -> 1 | AL24: =J24 -> 1 | AM24: =K24 -> 0.46 | AN24: =$R$2 + SUMPRODUCT(AD24:AM24,$S$2:$AB$2) -> -0.30723472 | AO24: =1/(1+EXP(-AN24)) -> 0.42378986
A25: CUST1023 | B25: 19 | C25: 63300 | D25: 5 | E25: 63.47 | F25: 4 | G25: 0.6 | H25: 269 | I25: 1 | J25: 0 | K25: 0.43 | L25: 0 | M25: =$R$2 + SUMPRODUCT(B25:K25,$S$2:$AB$2) -> 0.0190823 | N25: =1/(1+EXP(-M25)) -> 0.50477043 | O25: =IF(L25=1,N25,1-N25) -> 0.49522957 | P25: =LN(O25) -> -0.70273385 | Q25: Non-Negative Variables | R25: Unchecked | AD25: =B25 -> 19 | AE25: =C25 -> 63300 | AF25: =D25 -> 5 | AG25: =E25*0.85 -> 53.9495 | AH25: =F25*0.9 -> 3.6 | AI25: =G25 -> 0.6 | AJ25: =H25*1.2 -> 322.8 | AK25: =I25 -> 1 | AL25: =J25 -> 0 | AM25: =K25 -> 0.43 | AN25: =$R$2 + SUMPRODUCT(AD25:AM25,$S$2:$AB$2) -> -0.46501218 | AO25: =1/(1+EXP(-AN25)) -> 0.38579747
A26: CUST1024 | B26: 38 | C26: 58600 | D26: 10 | E26: 77.51 | F26: 4 | G26: 0.2 | H26: 321 | I26: 0 | J26: 1 | K26: 0.23 | L26: 0 | M26: =$R$2 + SUMPRODUCT(B26:K26,$S$2:$AB$2) -> -0.45802038 | N26: =1/(1+EXP(-M26)) -> 0.38745555 | O26: =IF(L26=1,N26,1-N26) -> 0.61254445 | P26: =LN(O26) -> -0.49013377 | Q26: Solving Method | R26: GRG Nonlinear | AD26: =B26 -> 38 | AE26: =C26 -> 58600 | AF26: =D26 -> 10 | AG26: =E26*0.85 -> 65.8835 | AH26: =F26*0.9 -> 3.6 | AI26: =G26 -> 0.2 | AJ26: =H26*1.2 -> 385.2 | AK26: =I26 -> 0 | AL26: =J26 -> 1 | AM26: =K26 -> 0.23 | AN26: =$R$2 + SUMPRODUCT(AD26:AM26,$S$2:$AB$2) -> -1.030288 | AO26: =1/(1+EXP(-AN26)) -> 0.26302828
A27: CUST1025 | B27: 50 | C27: 44200 | D27: 12 | E27: 51.66 | F27: 3 | G27: 0.56 | H27: 86 | I27: 1 | J27: 1 | K27: 0.34 | L27: 1 | M27: =$R$2 + SUMPRODUCT(B27:K27,$S$2:$AB$2) -> 1.7852698 | N27: =1/(1+EXP(-M27)) -> 0.85634636 | O27: =IF(L27=1,N27,1-N27) -> 0.85634636 | P27: =LN(O27) -> -0.15508036 | AD27: =B27 -> 50 | AE27: =C27 -> 44200 | AF27: =D27 -> 12 | AG27: =E27*0.85 -> 43.911 | AH27: =F27*0.9 -> 2.7 | AI27: =G27 -> 0.56 | AJ27: =H27*1.2 -> 103.2 | AK27: =I27 -> 1 | AL27: =J27 -> 1 | AM27: =K27 -> 0.34 | AN27: =$R$2 + SUMPRODUCT(AD27:AM27,$S$2:$AB$2) -> 1.5473209 | AO27: =1/(1+EXP(-AN27)) -> 0.82452646
A28: CUST1026 | B28: 29 | C28: 56300 | D28: 7 | E28: 95.52 | F28: 1 | G28: 0.57 | H28: 320 | I28: 1 | J28: 1 | K28: 0.58 | L28: 1 | M28: =$R$2 + SUMPRODUCT(B28:K28,$S$2:$AB$2) -> 0.66037577 | N28: =1/(1+EXP(-M28)) -> 0.65934479 | O28: =IF(L28=1,N28,1-N28) -> 0.65934479 | P28: =LN(O28) -> -0.41650867 | Q28: Note: R2:AB2 already hold the MLE-optimal coefficients (solved via Newton-Raphson MLE in Python, the same objective Excel Solver maximizes). Running Data > Solver on R4/Max/R2:AB2 in Excel will reconverge to these same values from any starting point. | AD28: =B28 -> 29 | AE28: =C28 -> 56300 | AF28: =D28 -> 7 | AG28: =E28*0.85 -> 81.192 | AH28: =F28*0.9 -> 0.9 | AI28: =G28 -> 0.57 | AJ28: =H28*1.2 -> 384 | AK28: =I28 -> 1 | AL28: =J28 -> 1 | AM28: =K28 -> 0.58 | AN28: =$R$2 + SUMPRODUCT(AD28:AM28,$S$2:$AB$2) -> 0.087789446 | AO28: =1/(1+EXP(-AN28)) -> 0.52193328
A29: CUST1027 | B29: 39 | C29: 48100 | D29: 1 | E29: 43.08 | F29: 1 | G29: 0.34 | H29: 32 | I29: 0 | J29: 1 | K29: 0.34 | L29: 0 | M29: =$R$2 + SUMPRODUCT(B29:K29,$S$2:$AB$2) -> -1.202192 | N29: =1/(1+EXP(-M29)) -> 0.2310855 | O29: =IF(L29=1,N29,1-N29) -> 0.7689145 | P29: =LN(O29) -> -0.2627755 | AD29: =B29 -> 39 | AE29: =C29 -> 48100 | AF29: =D29 -> 1 | AG29: =E29*0.85 -> 36.618 | AH29: =F29*0.9 -> 0.9 | AI29: =G29 -> 0.34 | AJ29: =H29*1.2 -> 38.4 | AK29: =I29 -> 0 | AL29: =J29 -> 1 | AM29: =K29 -> 0.34 | AN29: =$R$2 + SUMPRODUCT(AD29:AM29,$S$2:$AB$2) -> -1.3374535 | AO29: =1/(1+EXP(-AN29)) -> 0.20792913
A30: CUST1028 | B30: 61 | C30: 57000 | D30: 8 | E30: 107.8 | F30: 5 | G30: 0.42 | H30: 336 | I30: 1 | J30: 1 | K30: 0.11 | L30: 1 | M30: =$R$2 + SUMPRODUCT(B30:K30,$S$2:$AB$2) -> 0.25022585 | N30: =1/(1+EXP(-M30)) -> 0.56223209 | O30: =IF(L30=1,N30,1-N30) -> 0.56223209 | P30: =LN(O30) -> -0.57584054 | AD30: =B30 -> 61 | AE30: =C30 -> 57000 | AF30: =D30 -> 8 | AG30: =E30*0.85 -> 91.63 | AH30: =F30*0.9 -> 4.5 | AI30: =G30 -> 0.42 | AJ30: =H30*1.2 -> 403.2 | AK30: =I30 -> 1 | AL30: =J30 -> 1 | AM30: =K30 -> 0.11 | AN30: =$R$2 + SUMPRODUCT(AD30:AM30,$S$2:$AB$2) -> -0.41195486 | AO30: =1/(1+EXP(-AN30)) -> 0.39844348
A31: CUST1029 | B31: 42 | C31: 66900 | D31: 8 | E31: 21.31 | F31: 6 | G31: 0.38 | H31: 51 | I31: 0 | J31: 1 | K31: 0.36 | L31: 1 | M31: =$R$2 + SUMPRODUCT(B31:K31,$S$2:$AB$2) -> 0.78600609 | N31: =1/(1+EXP(-M31)) -> 0.68697312 | O31: =IF(L31=1,N31,1-N31) -> 0.68697312 | P31: =LN(O31) -> -0.37546012 | AD31: =B31 -> 42 | AE31: =C31 -> 66900 | AF31: =D31 -> 8 | AG31: =E31*0.85 -> 18.1135 | AH31: =F31*0.9 -> 5.4 | AI31: =G31 -> 0.38 | AJ31: =H31*1.2 -> 61.2 | AK31: =I31 -> 0 | AL31: =J31 -> 1 | AM31: =K31 -> 0.36 | AN31: =$R$2 + SUMPRODUCT(AD31:AM31,$S$2:$AB$2) -> 0.61469811 | AO31: =1/(1+EXP(-AN31)) -> 0.64901176
A32: CUST1030 | B32: 66 | C32: 83500 | D32: 5 | E32: 75.87 | F32: 6 | G32: 0.15 | H32: 79 | I32: 1 | J32: 1 | K32: 0.24 | L32: 0 | M32: =$R$2 + SUMPRODUCT(B32:K32,$S$2:$AB$2) -> 1.1042523 | N32: =1/(1+EXP(-M32)) -> 0.75105601 | O32: =IF(L32=1,N32,1-N32) -> 0.24894399 | P32: =LN(O32) -> -1.3905273 | AD32: =B32 -> 66 | AE32: =C32 -> 83500 | AF32: =D32 -> 5 | AG32: =E32*0.85 -> 64.4895 | AH32: =F32*0.9 -> 5.4 | AI32: =G32 -> 0.15 | AJ32: =H32*1.2 -> 94.8 | AK32: =I32 -> 1 | AL32: =J32 -> 1 | AM32: =K32 -> 0.24 | AN32: =$R$2 + SUMPRODUCT(AD32:AM32,$S$2:$AB$2) -> 0.79076382 | AO32: =1/(1+EXP(-AN32)) -> 0.68799531
A33: CUST1031 | B33: 44 | C33: 32700 | D33: 7 | E33: 76.89 | F33: 3 | G33: 0.56 | H33: 186 | I33: 1 | J33: 0 | K33: 0.3 | L33: 0 | M33: =$R$2 + SUMPRODUCT(B33:K33,$S$2:$AB$2) -> -0.26706397 | N33: =1/(1+EXP(-M33)) -> 0.43362803 | O33: =IF(L33=1,N33,1-N33) -> 0.56637197 | P33: =LN(O33) -> -0.56850422 | AD33: =B33 -> 44 | AE33: =C33 -> 32700 | AF33: =D33 -> 7 | AG33: =E33*0.85 -> 65.3565 | AH33: =F33*0.9 -> 2.7 | AI33: =G33 -> 0.56 | AJ33: =H33*1.2 -> 223.2 | AK33: =I33 -> 1 | AL33: =J33 -> 0 | AM33: =K33 -> 0.3 | AN33: =$R$2 + SUMPRODUCT(AD33:AM33,$S$2:$AB$2) -> -0.67100998 | AO33: =1/(1+EXP(-AN33)) -> 0.33827073
A34: CUST1032 | B34: 59 | C34: 93400 | D34: 4 | E34: 45.11 | F34: 6 | G34: 0.53 | H34: 174 | I34: 1 | J34: 1 | K34: 0.32 | L34: 1 | M34: =$R$2 + SUMPRODUCT(B34:K34,$S$2:$AB$2) -> 0.98218082 | N34: =1/(1+EXP(-M34)) -> 0.72754072 | O34: =IF(L34=1,N34,1-N34) -> 0.72754072 | P34: =LN(O34) -> -0.3180853 | AD34: =B34 -> 59 | AE34: =C34 -> 93400 | AF34: =D34 -> 4 | AG34: =E34*0.85 -> 38.3435 | AH34: =F34*0.9 -> 5.4 | AI34: =G34 -> 0.53 | AJ34: =H34*1.2 -> 208.8 | AK34: =I34 -> 1 | AL34: =J34 -> 1 | AM34: =K34 -> 0.32 | AN34: =$R$2 + SUMPRODUCT(AD34:AM34,$S$2:$AB$2) -> 0.62127023 | AO34: =1/(1+EXP(-AN34)) -> 0.65050739
A35: CUST1033 | B35: 45 | C35: 19900 | D35: 7 | E35: 75.61 | F35: 5 | G35: 0.37 | H35: 106 | I35: 1 | J35: 0 | K35: 0.43 | L35: 1 | M35: =$R$2 + SUMPRODUCT(B35:K35,$S$2:$AB$2) -> -0.06305041 | N35: =1/(1+EXP(-M35)) -> 0.48424262 | O35: =IF(L35=1,N35,1-N35) -> 0.48424262 | P35: =LN(O35) -> -0.72516922 | AD35: =B35 -> 45 | AE35: =C35 -> 19900 | AF35: =D35 -> 7 | AG35: =E35*0.85 -> 64.2685 | AH35: =F35*0.9 -> 4.5 | AI35: =G35 -> 0.37 | AJ35: =H35*1.2 -> 127.2 | AK35: =I35 -> 1 | AL35: =J35 -> 0 | AM35: =K35 -> 0.43 | AN35: =$R$2 + SUMPRODUCT(AD35:AM35,$S$2:$AB$2) -> -0.39550188 | AO35: =1/(1+EXP(-AN35)) -> 0.40239354
A36: CUST1034 | B36: 33 | C36: 52300 | D36: 4 | E36: 96.99 | F36: 6 | G36: 0.08 | H36: 63 | I36: 0 | J36: 1 | K36: 0.66 | L36: 0 | M36: =$R$2 + SUMPRODUCT(B36:K36,$S$2:$AB$2) -> 0.59191113 | N36: =1/(1+EXP(-M36)) -> 0.64380353 | O36: =IF(L36=1,N36,1-N36) -> 0.35619647 | P36: =LN(O36) -> -1.0322728 | AD36: =B36 -> 33 | AE36: =C36 -> 52300 | AF36: =D36 -> 4 | AG36: =E36*0.85 -> 82.4415 | AH36: =F36*0.9 -> 5.4 | AI36: =G36 -> 0.08 | AJ36: =H36*1.2 -> 75.6 | AK36: =I36 -> 0 | AL36: =J36 -> 1 | AM36: =K36 -> 0.66 | AN36: =$R$2 + SUMPRODUCT(AD36:AM36,$S$2:$AB$2) -> 0.25429253 | AO36: =1/(1+EXP(-AN36)) -> 0.56323276
A37: CUST1035 | B37: 32 | C37: 65600 | D37: 7 | E37: 10 | F37: 1 | G37: 0.12 | H37: 76 | I37: 0 | J37: 0 | K37: 0.32 | L37: 0 | M37: =$R$2 + SUMPRODUCT(B37:K37,$S$2:$AB$2) -> -1.2982569 | N37: =1/(1+EXP(-M37)) -> 0.21445852 | O37: =IF(L37=1,N37,1-N37) -> 0.78554148 | P37: =LN(O37) -> -0.24138202 | AD37: =B37 -> 32 | AE37: =C37 -> 65600 | AF37: =D37 -> 7 | AG37: =E37*0.85 -> 8.5 | AH37: =F37*0.9 -> 0.9 | AI37: =G37 -> 0.12 | AJ37: =H37*1.2 -> 91.2 | AK37: =I37 -> 0 | AL37: =J37 -> 0 | AM37: =K37 -> 0.32 | AN37: =$R$2 + SUMPRODUCT(AD37:AM37,$S$2:$AB$2) -> -1.4175343 | AO37: =1/(1+EXP(-AN37)) -> 0.19504842
A38: CUST1036 | B38: 64 | C38: 60100 | D38: 5 | E38: 77.57 | F38: 3 | G38: 0.5 | H38: 316 | I38: 1 | J38: 1 | K38: 0.26 | L38: 0 | M38: =$R$2 + SUMPRODUCT(B38:K38,$S$2:$AB$2) -> -0.50007711 | N38: =1/(1+EXP(-M38)) -> 0.37752255 | O38: =IF(L38=1,N38,1-N38) -> 0.62247745 | P38: =LN(O38) -> -0.47404787 | AD38: =B38 -> 64 | AE38: =C38 -> 60100 | AF38: =D38 -> 5 | AG38: =E38*0.85 -> 65.9345 | AH38: =F38*0.9 -> 2.7 | AI38: =G38 -> 0.5 | AJ38: =H38*1.2 -> 379.2 | AK38: =I38 -> 1 | AL38: =J38 -> 1 | AM38: =K38 -> 0.26 | AN38: =$R$2 + SUMPRODUCT(AD38:AM38,$S$2:$AB$2) -> -1.0551013 | AO38: =1/(1+EXP(-AN38)) -> 0.25824672
A39: CUST1037 | B39: 68 | C39: 43800 | D39: 12 | E39: 10 | F39: 3 | G39: 0.38 | H39: 321 | I39: 1 | J39: 0 | K39: 0.29 | L39: 1 | M39: =$R$2 + SUMPRODUCT(B39:K39,$S$2:$AB$2) -> -1.3279874 | N39: =1/(1+EXP(-M39)) -> 0.20949246 | O39: =IF(L39=1,N39,1-N39) -> 0.20949246 | P39: =LN(O39) -> -1.5630675 | AD39: =B39 -> 68 | AE39: =C39 -> 43800 | AF39: =D39 -> 12 | AG39: =E39*0.85 -> 8.5 | AH39: =F39*0.9 -> 2.7 | AI39: =G39 -> 0.38 | AJ39: =H39*1.2 -> 385.2 | AK39: =I39 -> 1 | AL39: =J39 -> 0 | AM39: =K39 -> 0.29 | AN39: =$R$2 + SUMPRODUCT(AD39:AM39,$S$2:$AB$2) -> -1.7526195 | AO39: =1/(1+EXP(-AN39)) -> 0.14771711
A40: CUST1038 | B40: 61 | C40: 51300 | D40: 5 | E40: 40.86 | F40: 6 | G40: 0.58 | H40: 81 | I40: 1 | J40: 1 | K40: 0.15 | L40: 0 | M40: =$R$2 + SUMPRODUCT(B40:K40,$S$2:$AB$2) -> 0.54706751 | N40: =1/(1+EXP(-M40)) -> 0.63345496 | O40: =IF(L40=1,N40,1-N40) -> 0.36654504 | P40: =LN(O40) -> -1.0036339 | AD40: =B40 -> 61 | AE40: =C40 -> 51300 | AF40: =D40 -> 5 | AG40: =E40*0.85 -> 34.731 | AH40: =F40*0.9 -> 5.4 | AI40: =G40 -> 0.58 | AJ40: =H40*1.2 -> 97.2 | AK40: =I40 -> 1 | AL40: =J40 -> 1 | AM40: =K40 -> 0.15 | AN40: =$R$2 + SUMPRODUCT(AD40:AM40,$S$2:$AB$2) -> 0.30181925 | AO40: =1/(1+EXP(-AN40)) -> 0.57488719
...

Sheet Before vs After
A1: Inflationary Pressure Scenario — Before vs. After KPI Comparison
A3: KPI | B3: Baseline (Pre-Inflation) | C3: Intervention (Post-Inflation Shock) | D3: Δ Change | E3: % Change
A4: Average Probability of Response | B4: ='MLE Model'!R6 -> 0.44669992 | C4: ='MLE Model'!R13 -> 0.37524111 | D4: =C4-B4 -> -0.071458811 | E4: =(C4-B4)/B4 -> -0.1599705
A5: Total Expected Revenue ($) | B5: ='MLE Model'!R7 -> 15193.308 | C5: ='MLE Model'!R14 -> 10827.1 | D5: =C5-B5 -> -4366.2086 | E5: =(C5-B5)/B5 -> -0.28737708
A6: # Customers Targeted (p > 0.5) | B6: ='MLE Model'!R8 -> 212 | C6: ='MLE Model'!R15 -> 145 | D6: =C6-B6 -> -67 | E6: =(C6-B6)/B6 -> -0.31603774
A7: Total Marketing Cost ($) | B7: ='MLE Model'!R9 -> 1060 | C7: ='MLE Model'!R16 -> 725 | D7: =C7-B7 -> -335 | E7: =(C7-B7)/B7 -> -0.31603774
A8: Cost per Acquisition (CPA, $) | B8: ='MLE Model'!R11 -> 7.517757 | C8: ='MLE Model'!R18 -> 7.5384394 | D8: =C8-B8 -> 0.020682425 | E8: =(C8-B8)/B8 -> 0.002751143
A11: Interpretation: Coefficients (Model sheet, R2:AB2) are fixed across both scenarios — they represent the stable historical relationship between customer attributes and campaign response, estimated once via Maximum Likelihood. Phase 2 changes only the customer-level inputs (AvgOrderValue -15%, WebsiteVisits -10%, DaysSinceLastPurchase +20%), so every KPI shift above is attributable purely to those three shocks acting through the fixed logistic weights. Revenue falls disproportionately because probability drops AND per-conversion order value drops simultaneously (a compounding effect), while CPA rises because the same $5/customer spend converts fewer of the remaining 'fence-sitter' customers near p=0.5.
